<?xml version="1.0" encoding="utf-8"?>
<robot>
  <link
    name="lowerarm_preroll_d">
    <inertial>
      <origin
        xyz="0.0192090313803226 -0.000209732444885397 -0.00477606520095217"
        rpy="0 0 0" />
      <mass
        value="0.0573922743530686" />
      <inertia
        ixx="5.98272304285402E-07"
        ixy="-9.55132100709239E-09"
        ixz="2.00959509125472E-06"
        iyy="7.34863588332809E-06"
        iyz="2.84343934345717E-09"
        izz="6.7503906079721E-06" />
    </inertial>
    <visual>
      <origin
        xyz="0 0 0"
        rpy="0 0 0" />
      <geometry>
        <mesh
          filename="package://gummi_ee_$(env ROS_GUMMI_EE)/meshes/lowerarm_preroll_d.stl" />
      </geometry>
      <material
        name="">
        <color
          rgba="0.792156862745098 0.819607843137255 0.933333333333333 1" />
      </material>
    </visual>
    <collision>
      <origin
        xyz="0 0 0"
        rpy="0 0 0" />
      <geometry>
        <mesh
          filename="package://gummi_ee_$(env ROS_GUMMI_EE)/meshes/lowerarm_preroll_d_CH.stl" />
      </geometry>
    </collision>
  </link>
  <joint
    name="fastswitch"
    type="fixed">
    <origin
      xyz="0.00037 0.10187 -0.021"
      rpy="1.57079632679 -1.57079632679 0" />
    <parent
      link="lowerarm_preroll_u" />
    <child
      link="lowerarm_preroll_d" />
    <axis
      xyz="0 0 1" />
    <!-- <limit
      lower="-1.5708"
      upper="1.5708"
      effort="0"
      velocity="0" /> -->
    <limit effort="0" lower="-0.85" upper="0.65" velocity="1.0"/>
  </joint>
  <link
    name="lowerarm">
    <inertial>
      <origin
        xyz="0.076518166900465 0.000154587846369382 0.00668942647768447"
        rpy="0 0 0" />
      <mass
        value="0.214658222402075" />
      <inertia
        ixx="2.53797627665925E-05"
        ixy="-3.78406001691015E-09"
        ixz="1.36269412886066E-05"
        iyy="0.000325304336296306"
        iyz="3.75496083335353E-07"
        izz="0.000302080494837117" />
    </inertial>
    <visual>
      <origin
        xyz="0 0 0"
        rpy="0 0 0" />
      <geometry>
        <mesh
          filename="package://gummi_ee_$(env ROS_GUMMI_EE)/meshes/j6_link.stl" />
      </geometry>
      <material
        name="">
        <color
          rgba="0.792156862745098 0.819607843137255 0.933333333333333 1" />
      </material>
    </visual>
    <collision>
      <origin
        xyz="0 0 0"
        rpy="0 0 0" />
      <geometry>
        <mesh
          filename="package://gummi_ee_$(env ROS_GUMMI_EE)/meshes/j6_link_CH.stl" />
      </geometry>
    </collision>
  </link>
  <joint
    name="forearm_roll"
    type="continuous">
    <origin
      xyz="0 0 0.03987"
      rpy="0 0 3.14159265359" />
    <parent
      link="lowerarm_preroll_d" />
    <child
      link="lowerarm" />
    <axis
      xyz="0 0 -1" />
    <limit
      effort="0"
      velocity="1" />
  </joint>
  <link
    name="wrist">
    <inertial>
      <origin
        xyz="0.0484512742480244 0.0139768664666073 0.000956995637939325"
        rpy="0 0 0" />
      <mass
        value="0.0644774651698934" />
      <inertia
        ixx="8.67406414845019E-06"
        ixy="-1.3193756197629E-05"
        ixz="-3.41916035169704E-06"
        iyy="4.217442276821E-05"
        iyz="-4.04257224014858E-07"
        izz="4.91399139463636E-05" />
    </inertial>
    <visual>
      <origin
        xyz="0 0 0"
        rpy="0 0 0" />
      <geometry>
        <mesh
          filename="package://gummi_ee_$(env ROS_GUMMI_EE)/meshes/j7_Link.stl" />
      </geometry>
      <material
        name="">
        <color
          rgba="0.792156862745098 0.819607843137255 0.933333333333333 1" />
      </material>
    </visual>
    <collision>
      <origin
        xyz="0 0 0"
        rpy="0 0 0" />
      <geometry>
        <mesh
          filename="package://gummi_ee_$(env ROS_GUMMI_EE)/meshes/j7_Link_CH.stl" />
      </geometry>
    </collision>
  </link>
  <joint
    name="wrist_pitch"
    type="revolute">
    <origin
      xyz="0.019 0 -0.16357"
      rpy="0 1.57079632679 0" />
    <parent
      link="lowerarm" />
    <child
      link="wrist" />
    <axis
      xyz="0 0 -1" />
    <limit
      lower="-1"
      upper="1"
      effort="0"
      velocity="0" />
  </joint>
    <link
    name="pointer">
    <inertial>
      <origin
        xyz="0.0484512742480244 0.0139768664666073 0.000956995637939325"
        rpy="0 0 0" />
      <mass
        value="0.0644774651698934" />
      <inertia
        ixx="8.67406414845019E-06"
        ixy="-1.3193756197629E-05"
        ixz="-3.41916035169704E-06"
        iyy="4.217442276821E-05"
        iyz="-4.04257224014858E-07"
        izz="4.91399139463636E-05" />
    </inertial>
    <visual>
      <origin
        xyz="0 0 0"
        rpy="0 0 0" />
      <geometry>
        <mesh
          filename="package://gummi_ee_$(env ROS_GUMMI_EE)/meshes/pointer_gripper_EIH.stl" />
      </geometry>
      <material
        name="">
        <color
          rgba="0.792156862745098 0.819607843137255 0.933333333333333 1" />
      </material>
    </visual>
    <collision>
      <origin
        xyz="0 0 0"
        rpy="0 0 0" />
      <geometry>
        <mesh
          filename="package://gummi_ee_$(env ROS_GUMMI_EE)/meshes/pointer_gripper_EIH_CH.stl" />
      </geometry>
    </collision>
  </link>
  <joint
    name="end_effector"
    type="fixed">
    <origin
      xyz="0.0966 0 -0.0202"
      rpy="0 -1.57079632679 3.14159265359" />
    <parent
      link="wrist" />
    <child
      link="pointer" />
    <axis
      xyz="0 0 0" />
  </joint>
</robot>
